Workbook

Sheet README
A1: Elevator & Escalator Big 4 Benchmark, FY2025
A2: KONE vs Otis, Schindler and TK Elevator, plus a pro forma KONE + TKE view
A4: Question: how does KONE compare with its three largest peers on scale, business mix and profitability,
A5: and what would a combined KONE + TK Elevator look like if the announced deal closes?
A7: Workflow
A8: 1. Inputs: exchange rates and synergy assumptions (yellow cells can be changed).
A9: 2. Raw_Data: every reported figure in its original currency, one row per data point, with its source.
A10: 3. Benchmark: figures converted to EUR with SUMIFS lookups; KPIs and ranks are formulas.
A11: 4. ProForma: KONE + TKE combined, with a synergy-realisation scenario selector.
A12: 5. Checks: automated tests that the data adds up and matches published totals.
A13: 6. Dashboard: charts linked to the Benchmark and ProForma sheets.
A15: Colour code: blue = hardcoded input from a source, black = formula, green = link to another sheet,
... A27: Illustrative analysis based on public company reports. Not investment advice.

Sheet Inputs
A1: Inputs and assumptions
A3: Item | B3: Value | C3: Unit | D3: Source / note
A4: EUR/USD (2025 average) | B4: 1.13 | C4: USD per EUR | D4: ECB reference rate, 2025 annual average (Bank of Finland, suomenpankki.fi)
A5: EUR/CHF (2025 average) | B5: 0.937 | C5: CHF per EUR | D5: ECB reference rate, 2025 annual average (Bank of Finland, suomenpankki.fi)
A6: EUR/EUR | B6: 1 | D6: Identity rate so every currency can be looked up the same way
A7: Announced run-rate cost synergies | B7: 700 | C7: EUR m | D7: KONE deal announcement, 29 Apr 2026 (Reuters, Yahoo Finance)
A8: Synergy scenario (choose) | B8: Base | D8: Dropdown: Low / Base / Full
A11: Synergy realisation by scenario
A12: Scenario | B12: Share of EUR 700m realised | D12: Note
A13: Low | B13: 0.25 | D13: Early integration, divestments dilute savings
A14: Base | B14: 0.5 | D14: Roughly halfway through the three-year ramp-up
A15: Full | B15: 1 | D15: Full run-rate, as guided within three years of closing
A17: Selected realisation | B17: =INDEX($B$13:$B$15,MATCH($B$8,$A$13:$A$15,0)) -> 0.5

Sheet Raw_Data
A1: Raw data: reported figures, original currency (never edited by formulas)
A3: Company | B3: Metric | C3: Value | D3: Unit | E3: Currency | F3: Period | G3: Source
A4: KONE | B4: Sales | C4: 11245.2 | D4: m | E4: EUR | F4: FY2025 | G4: KONE Financial Statement Bulletin & Annual Review 2025 (kone.com, 6 Feb 2026)
A5: KONE | B5: Sales prior year | C5: 11098.4 | D5: m | E5: EUR | F5: FY2024 | G5: KONE Financial Statement Bulletin & Annual Review 2025 (kone.com, 6 Feb 2026)
A6: KONE | B6: Orders received | C6: 9087.4 | D6: m | E6: EUR | F6: FY2025 | G6: KONE Financial Statement Bulletin & Annual Review 2025 (kone.com, 6 Feb 2026); excludes service contracts
A7: KONE | B7: Adjusted EBIT | C7: 1369.3 | D7: m | E7: EUR | F7: FY2025 | G7: KONE Financial Statement Bulletin & Annual Review 2025 (kone.com, 6 Feb 2026)
A8: KONE | B8: Adjusted EBIT margin | C8: 0.122 | D8: % | F8: FY2025 | G8: KONE Financial Statement Bulletin & Annual Review 2025 (kone.com, 6 Feb 2026)
A9: KONE | B9: Reported EBIT | C9: 1336.2 | D9: m | E9: EUR | F9: FY2025 | G9: KONE Financial Statement Bulletin & Annual Review 2025 (kone.com, 6 Feb 2026)
A10: KONE | B10: New equipment sales | C10: 4097.7 | D10: m | E10: EUR | F10: FY2025 | G10: KONE Financial Statement Bulletin & Annual Review 2025 (kone.com, 6 Feb 2026); New Building Solutions
A11: KONE | B11: Service sales | C11: 4753.6 | D11: m | E11: EUR | F11: FY2025 | G11: KONE Financial Statement Bulletin & Annual Review 2025 (kone.com, 6 Feb 2026)
A12: KONE | B12: Modernization sales | C12: 2394 | D12: m | E12: EUR | F12: FY2025 | G12: KONE Financial Statement Bulletin & Annual Review 2025 (kone.com, 6 Feb 2026)
A13: KONE | B13: Sales Americas | C13: 2812.1 | D13: m | E13: EUR | F13: FY2025 | G13: KONE Financial Statement Bulletin & Annual Review 2025 (kone.com, 6 Feb 2026)
A14: KONE | B14: Sales Europe | C14: 4524.4 | D14: m | E14: EUR | F14: FY2025 | G14: KONE Financial Statement Bulletin & Annual Review 2025 (kone.com, 6 Feb 2026)
A15: KONE | B15: Sales APMEA | C15: 1742.7 | D15: m | E15: EUR | F15: FY2025 | G15: KONE Financial Statement Bulletin & Annual Review 2025 (kone.com, 6 Feb 2026)
A16: KONE | B16: Sales Greater China | C16: 2166 | D16: m | E16: EUR | F16: FY2025 | G16: KONE Financial Statement Bulletin & Annual Review 2025 (kone.com, 6 Feb 2026)
A17: KONE | B17: US share of sales | C17: 0.21 | D17: % | F17: FY2025 | G17: KONE Financial Statement Bulletin & Annual Review 2025 (kone.com, 6 Feb 2026); largest country
A18: KONE | B18: Employees | C18: 64978 | D18: FTE | F18: Dec 2025 | G18: KONE Financial Statement Bulletin & Annual Review 2025 (kone.com, 6 Feb 2026)
A19: KONE | B19: Units under maintenance | C19: 1.8 | D19: m units | F19: Dec 2025 | G19: KONE Financial Statement Bulletin & Annual Review 2025 (kone.com, 6 Feb 2026); approx.
A20: Otis | B20: Sales | C20: 14431 | D20: m | E20: USD | F20: FY2025 | G20: Otis Q4/FY2025 earnings release (otisinvestors.com, 28 Jan 2026)
A21: Otis | B21: Sales prior year | C21: 14261 | D21: m | E21: USD | F21: FY2024 | G21: Otis Q4/FY2025 earnings release (otisinvestors.com, 28 Jan 2026)
A22: Otis | B22: Adjusted EBIT | C22: 2434 | D22: m | E22: USD | F22: FY2025 | G22: Otis Q4/FY2025 earnings release (otisinvestors.com, 28 Jan 2026); adjusted operating profit
A23: Otis | B23: Adjusted EBIT margin | C23: 0.169 | D23: % | F23: FY2025 | G23: Otis Q4/FY2025 earnings release (otisinvestors.com, 28 Jan 2026)
A24: Otis | B24: Reported EBIT | C24: 2133 | D24: m | E24: USD | F24: FY2025 | G24: Otis Q4/FY2025 earnings release (otisinvestors.com, 28 Jan 2026); GAAP operating profit
A25: Otis | B25: New equipment sales | C25: 4989 | D25: m | E25: USD | F25: FY2025 | G25: Otis Q4/FY2025 earnings release (otisinvestors.com, 28 Jan 2026)
A26: Otis | B26: Service sales | C26: 9442 | D26: m | E26: USD | F26: FY2025 | G26: Otis Q4/FY2025 earnings release (otisinvestors.com, 28 Jan 2026); Service segment incl. modernization
A27: Otis | B27: Employees | C27: 72000 | D27: people | F27: FY2025 | G27: Otis Q4/FY2025 earnings release (otisinvestors.com, 28 Jan 2026); approx.
A28: Otis | B28: Units under maintenance | C28: 2.5 | D28: m units | F28: FY2025 | G28: Otis Q4/FY2025 earnings release (otisinvestors.com, 28 Jan 2026); approx.
A29: Schindler | B29: Sales | C29: 10947 | D29: m | E29: CHF | F29: FY2025 | G29: Schindler Annual Report 2025 (reports.schindler.com)
A30: Schindler | B30: Sales prior year | C30: 11236 | D30: m | E30: CHF | F30: FY2024 | G30: Schindler Annual Report 2025 (reports.schindler.com); note 4 Revenue
A31: Schindler | B31: Orders received | C31: 11313 | D31: m | E31: CHF | F31: FY2025 | G31: Schindler Annual Report 2025 (reports.schindler.com)
A32: Schindler | B32: Adjusted EBIT margin | C32: 0.133 | D32: % | F32: FY2025 | G32: Schindler Annual Report 2025 (reports.schindler.com)
A33: Schindler | B33: Reported EBIT | C33: 1384 | D33: m | E33: CHF | F33: FY2025 | G33: Schindler Annual Report 2025 (reports.schindler.com)
A34: Schindler | B34: Sales EMEA | C34: 5255 | D34: m | E34: CHF | F34: FY2025 | G34: Schindler Annual Report 2025 (reports.schindler.com); note 4 Revenue
A35: Schindler | B35: Sales Americas | C35: 3214 | D35: m | E35: CHF | F35: FY2025 | G35: Schindler Annual Report 2025 (reports.schindler.com); note 4 Revenue
A36: Schindler | B36: Sales Asia-Pacific | C36: 2478 | D36: m | E36: CHF | F36: FY2025 | G36: Schindler Annual Report 2025 (reports.schindler.com); note 4 Revenue
A37: Schindler | B37: Employees | C37: 67381 | D37: people | F37: Dec 2025 | G37: Schindler Annual Report 2025 (reports.schindler.com); note 6 Employees
A38: TKE | B38: Sales | C38: 9200 | D38: m | E38: EUR | F38: FY Oct24-Sep25 | G38: TK Elevator FY2024/25 results release (tkelevator.com, 9 Dec 2025); 'EUR 9.2 billion' (rounded)
A39: TKE | B39: Adjusted EBIT margin | C39: 0.148 | D39: % | F39: FY Oct24-Sep25 | G39: TK Elevator FY2024/25 results release (tkelevator.com, 9 Dec 2025)
A40: TKE | B40: Adjusted EBITDA margin | C40: 0.175 | D40: % | F40: FY Oct24-Sep25 | G40: TK Elevator FY2024/25 results release (tkelevator.com, 9 Dec 2025)
A41: TKE | B41: Service and modernization share | C41: 0.65 | D41: % | F41: FY Oct24-Sep25 | G41: TK Elevator FY2024/25 results release (tkelevator.com, 9 Dec 2025)
...

Sheet Benchmark
A1: Benchmark, FY2025 (EUR millions unless stated)
A2: All values are formulas: SUMIFS on Raw_Data, divided by the company's FX rate from Inputs.
B3: KONE | C3: Otis | D3: Schindler | E3: TKE
A4: Metric | B4: KONE | C4: Otis | D4: Schindler | E4: TKE | F4: Rank of KONE | G4: Note
A5: Reporting currency | B5: EUR | C5: USD | D5: CHF | E5: EUR
A6: FX rate (per EUR) | B6: =IF(B5="USD",Inputs!$B$4,IF(B5="CHF",Inputs!$B$5,Inputs!$B$6)) -> 1 | C6: =IF(C5="USD",Inputs!$B$4,IF(C5="CHF",Inputs!$B$5,Inputs!$B$6)) -> 1.13 | D6: =IF(D5="USD",Inputs!$B$4,IF(D5="CHF",Inputs!$B$5,Inputs!$B$6)) -> 0.937 | E6: =IF(E5="USD",Inputs!$B$4,IF(E5="CHF",Inputs!$B$5,Inputs!$B$6)) -> 1
A7: Sales | B7: =IF(COUNTIFS(Raw_Data!$A$4:$A$46,B$3,Raw_Data!$B$4:$B$46,"Sales")=0,"n/d",SUMIFS(Raw_Data!$C$4:$C$46,Raw_Data!$A$4:$A$46,B$3,Raw_Data!$B$4:$B$46,"Sales")/B$6) -> 11245.2 | C7: =IF(COUNTIFS(Raw_Data!$A$4:$A$46,C$3,Raw_Data!$B$4:$B$46,"Sales")=0,"n/d",SUMIFS(Raw_Data!$C$4:$C$46,Raw_Data!$A$4:$A$46,C$3,Raw_Data!$B$4:$B$46,"Sales")/C$6) -> 12770.796 | D7: =IF(COUNTIFS(Raw_Data!$A$4:$A$46,D$3,Raw_Data!$B$4:$B$46,"Sales")=0,"n/d",SUMIFS(Raw_Data!$C$4:$C$46,Raw_Data!$A$4:$A$46,D$3,Raw_Data!$B$4:$B$46,"Sales")/D$6) -> 11683.031 | E7: =IF(COUNTIFS(Raw_Data!$A$4:$A$46,E$3,Raw_Data!$B$4:$B$46,"Sales")=0,"n/d",SUMIFS(Raw_Data!$C$4:$C$46,Raw_Data!$A$4:$A$46,E$3,Raw_Data!$B$4:$B$46,"Sales")/E$6) -> 9200 | F7: =IF(ISNUMBER(B7),SUMPRODUCT(--ISNUMBER(B7:E7),--(B7:E7>B7))+1&" of "&COUNT(B7:E7),"n/d") -> 3 of 4 | G7: Converted at 2025 average rates
A8: Sales growth, reported (%) | B8: =IF(COUNTIFS(Raw_Data!$A$4:$A$46,B$3,Raw_Data!$B$4:$B$46,"Sales prior year")=0,"n/d",SUMIFS(Raw_Data!$C$4:$C$46,Raw_Data!$A$4:$A$46,B$3,Raw_Data!$B$4:$B$46,"Sales")/SUMIFS(Raw_Data!$C$4:$C$46,Raw_Data!$A$4:$A$46,B$3,Raw_Data!$B$4:$B$46,"Sales prior year")-1) -> 0.013227132 | C8: =IF(COUNTIFS(Raw_Data!$A$4:$A$46,C$3,Raw_Data!$B$4:$B$46,"Sales prior year")=0,"n/d",SUMIFS(Raw_Data!$C$4:$C$46,Raw_Data!$A$4:$A$46,C$3,Raw_Data!$B$4:$B$46,"Sales")/SUMIFS(Raw_Data!$C$4:$C$46,Raw_Data!$A$4:$A$46,C$3,Raw_Data!$B$4:$B$46,"Sales prior year")-1) -> 0.011920623 | D8: =IF(COUNTIFS(Raw_Data!$A$4:$A$46,D$3,Raw_Data!$B$4:$B$46,"Sales prior year")=0,"n/d",SUMIFS(Raw_Data!$C$4:$C$46,Raw_Data!$A$4:$A$46,D$3,Raw_Data!$B$4:$B$46,"Sales")/SUMIFS(Raw_Data!$C$4:$C$46,Raw_Data!$A$4:$A$46,D$3,Raw_Data!$B$4:$B$46,"Sales prior year")-1) -> -0.025720897 | E8: =IF(COUNTIFS(Raw_Data!$A$4:$A$46,E$3,Raw_Data!$B$4:$B$46,"Sales prior year")=0,"n/d",SUMIFS(Raw_Data!$C$4:$C$46,Raw_Data!$A$4:$A$46,E$3,Raw_Data!$B$4:$B$46,"Sales")/SUMIFS(Raw_Data!$C$4:$C$46,Raw_Data!$A$4:$A$46,E$3,Raw_Data!$B$4:$B$46,"Sales prior year")-1) -> n/d | F8: =IF(ISNUMBER(B8),SUMPRODUCT(--ISNUMBER(B8:E8),--(B8:E8>B8))+1&" of "&COUNT(B8:E8),"n/d") -> 1 of 3 | G8: In reporting currency; TKE prior-year sales not collected
A9: Orders received | B9: =IF(COUNTIFS(Raw_Data!$A$4:$A$46,B$3,Raw_Data!$B$4:$B$46,"Orders received")=0,"n/d",SUMIFS(Raw_Data!$C$4:$C$46,Raw_Data!$A$4:$A$46,B$3,Raw_Data!$B$4:$B$46,"Orders received")/B$6) -> 9087.4 | C9: =IF(COUNTIFS(Raw_Data!$A$4:$A$46,C$3,Raw_Data!$B$4:$B$46,"Orders received")=0,"n/d",SUMIFS(Raw_Data!$C$4:$C$46,Raw_Data!$A$4:$A$46,C$3,Raw_Data!$B$4:$B$46,"Orders received")/C$6) -> n/d | D9: =IF(COUNTIFS(Raw_Data!$A$4:$A$46,D$3,Raw_Data!$B$4:$B$46,"Orders received")=0,"n/d",SUMIFS(Raw_Data!$C$4:$C$46,Raw_Data!$A$4:$A$46,D$3,Raw_Data!$B$4:$B$46,"Orders received")/D$6) -> 12073.639 | E9: =IF(COUNTIFS(Raw_Data!$A$4:$A$46,E$3,Raw_Data!$B$4:$B$46,"Orders received")=0,"n/d",SUMIFS(Raw_Data!$C$4:$C$46,Raw_Data!$A$4:$A$46,E$3,Raw_Data!$B$4:$B$46,"Orders received")/E$6) -> n/d | G9: Otis and TKE do not publish a comparable total
A10: Adjusted EBIT margin (%) | B10: =IF(COUNTIFS(Raw_Data!$A$4:$A$46,B$3,Raw_Data!$B$4:$B$46,"Adjusted EBIT margin")=0,"n/d",SUMIFS(Raw_Data!$C$4:$C$46,Raw_Data!$A$4:$A$46,B$3,Raw_Data!$B$4:$B$46,"Adjusted EBIT margin")) -> 0.122 | C10: =IF(COUNTIFS(Raw_Data!$A$4:$A$46,C$3,Raw_Data!$B$4:$B$46,"Adjusted EBIT margin")=0,"n/d",SUMIFS(Raw_Data!$C$4:$C$46,Raw_Data!$A$4:$A$46,C$3,Raw_Data!$B$4:$B$46,"Adjusted EBIT margin")) -> 0.169 | D10: =IF(COUNTIFS(Raw_Data!$A$4:$A$46,D$3,Raw_Data!$B$4:$B$46,"Adjusted EBIT margin")=0,"n/d",SUMIFS(Raw_Data!$C$4:$C$46,Raw_Data!$A$4:$A$46,D$3,Raw_Data!$B$4:$B$46,"Adjusted EBIT margin")) -> 0.133 | E10: =IF(COUNTIFS(Raw_Data!$A$4:$A$46,E$3,Raw_Data!$B$4:$B$46,"Adjusted EBIT margin")=0,"n/d",SUMIFS(Raw_Data!$C$4:$C$46,Raw_Data!$A$4:$A$46,E$3,Raw_Data!$B$4:$B$46,"Adjusted EBIT margin")) -> 0.148 | F10: =IF(ISNUMBER(B10),SUMPRODUCT(--ISNUMBER(B10:E10),--(B10:E10>B10))+1&" of "&COUNT(B10:E10),"n/d") -> 4 of 4 | G10: Company-defined; see README caveats
A11: Adjusted EBIT | B11: =IF(ISNUMBER(B7),B7*B10,"n/d") -> 1371.9144 | C11: =IF(ISNUMBER(C7),C7*C10,"n/d") -> 2158.2646 | D11: =IF(ISNUMBER(D7),D7*D10,"n/d") -> 1553.8431 | E11: =IF(ISNUMBER(E7),E7*E10,"n/d") -> 1361.6 | F11: =IF(ISNUMBER(B11),SUMPRODUCT(--ISNUMBER(B11:E11),--(B11:E11>B11))+1&" of "&COUNT(B11:E11),"n/d") -> 3 of 4 | G11: Sales x adjusted margin (keeps all four on one basis)
A12: Reported EBIT margin (%) | B12: =IF(COUNTIFS(Raw_Data!$A$4:$A$46,B$3,Raw_Data!$B$4:$B$46,"Reported EBIT")=0,"n/d",SUMIFS(Raw_Data!$C$4:$C$46,Raw_Data!$A$4:$A$46,B$3,Raw_Data!$B$4:$B$46,"Reported EBIT")/SUMIFS(Raw_Data!$C$4:$C$46,Raw_Data!$A$4:$A$46,B$3,Raw_Data!$B$4:$B$46,"Sales")) -> 0.11882403 | C12: =IF(COUNTIFS(Raw_Data!$A$4:$A$46,C$3,Raw_Data!$B$4:$B$46,"Reported EBIT")=0,"n/d",SUMIFS(Raw_Data!$C$4:$C$46,Raw_Data!$A$4:$A$46,C$3,Raw_Data!$B$4:$B$46,"Reported EBIT")/SUMIFS(Raw_Data!$C$4:$C$46,Raw_Data!$A$4:$A$46,C$3,Raw_Data!$B$4:$B$46,"Sales")) -> 0.1478068 | D12: =IF(COUNTIFS(Raw_Data!$A$4:$A$46,D$3,Raw_Data!$B$4:$B$46,"Reported EBIT")=0,"n/d",SUMIFS(Raw_Data!$C$4:$C$46,Raw_Data!$A$4:$A$46,D$3,Raw_Data!$B$4:$B$46,"Reported EBIT")/SUMIFS(Raw_Data!$C$4:$C$46,Raw_Data!$A$4:$A$46,D$3,Raw_Data!$B$4:$B$46,"Sales")) -> 0.12642733 | E12: =IF(COUNTIFS(Raw_Data!$A$4:$A$46,E$3,Raw_Data!$B$4:$B$46,"Reported EBIT")=0,"n/d",SUMIFS(Raw_Data!$C$4:$C$46,Raw_Data!$A$4:$A$46,E$3,Raw_Data!$B$4:$B$46,"Reported EBIT")/SUMIFS(Raw_Data!$C$4:$C$46,Raw_Data!$A$4:$A$46,E$3,Raw_Data!$B$4:$B$46,"Sales")) -> n/d | F12: =IF(ISNUMBER(B12),SUMPRODUCT(--ISNUMBER(B12:E12),--(B12:E12>B12))+1&" of "&COUNT(B12:E12),"n/d") -> 3 of 3 | G12: TKE does not publish reported EBIT in its results release
A13: Service & modernization share (%) | B13: =IF(COUNTIFS(Raw_Data!$A$4:$A$46,B$3,Raw_Data!$B$4:$B$46,"Service and modernization share")>0,SUMIFS(Raw_Data!$C$4:$C$46,Raw_Data!$A$4:$A$46,B$3,Raw_Data!$B$4:$B$46,"Service and modernization share"),IF(COUNTIFS(Raw_Data!$A$4:$A$46,B$3,Raw_Data!$B$4:$B$46,"Service sales")=0,"n/d",(SUMIFS(Raw_Data!$C$4:$C$46,Raw_Data!$A$4:$A$46,B$3,Raw_Data!$B$4:$B$46,"Service sales")+SUMIFS(Raw_Data!$C$4:$C$46,Raw_Data!$A$4:$A$46,B$3,Raw_Data!$B$4:$B$46,"Modernization sales"))/SUMIFS(Raw_Data!$C$4:$C$46,Raw_Data!$A$4:$A$46,B$3,Raw_Data!$B$4:$B$46,"Sales"))) -> 0.63561342 | C13: =IF(COUNTIFS(Raw_Data!$A$4:$A$46,C$3,Raw_Data!$B$4:$B$46,"Service and modernization share")>0,SUMIFS(Raw_Data!$C$4:$C$46,Raw_Data!$A$4:$A$46,C$3,Raw_Data!$B$4:$B$46,"Service and modernization share"),IF(COUNTIFS(Raw_Data!$A$4:$A$46,C$3,Raw_Data!$B$4:$B$46,"Service sales")=0,"n/d",(SUMIFS(Raw_Data!$C$4:$C$46,Raw_Data!$A$4:$A$46,C$3,Raw_Data!$B$4:$B$46,"Service sales")+SUMIFS(Raw_Data!$C$4:$C$46,Raw_Data!$A$4:$A$46,C$3,Raw_Data!$B$4:$B$46,"Modernization sales"))/SUMIFS(Raw_Data!$C$4:$C$46,Raw_Data!$A$4:$A$46,C$3,Raw_Data!$B$4:$B$46,"Sales"))) -> 0.65428591 | D13: =IF(COUNTIFS(Raw_Data!$A$4:$A$46,D$3,Raw_Data!$B$4:$B$46,"Service and modernization share")>0,SUMIFS(Raw_Data!$C$4:$C$46,Raw_Data!$A$4:$A$46,D$3,Raw_Data!$B$4:$B$46,"Service and modernization share"),IF(COUNTIFS(Raw_Data!$A$4:$A$46,D$3,Raw_Data!$B$4:$B$46,"Service sales")=0,"n/d",(SUMIFS(Raw_Data!$C$4:$C$46,Raw_Data!$A$4:$A$46,D$3,Raw_Data!$B$4:$B$46,"Service sales")+SUMIFS(Raw_Data!$C$4:$C$46,Raw_Data!$A$4:$A$46,D$3,Raw_Data!$B$4:$B$46,"Modernization sales"))/SUMIFS(Raw_Data!$C$4:$C$46,Raw_Data!$A$4:$A$46,D$3,Raw_Data!$B$4:$B$46,"Sales"))) -> n/d | E13: =IF(COUNTIFS(Raw_Data!$A$4:$A$46,E$3,Raw_Data!$B$4:$B$46,"Service and modernization share")>0,SUMIFS(Raw_Data!$C$4:$C$46,Raw_Data!$A$4:$A$46,E$3,Raw_Data!$B$4:$B$46,"Service and modernization share"),IF(COUNTIFS(Raw_Data!$A$4:$A$46,E$3,Raw_Data!$B$4:$B$46,"Service sales")=0,"n/d",(SUMIFS(Raw_Data!$C$4:$C$46,Raw_Data!$A$4:$A$46,E$3,Raw_Data!$B$4:$B$46,"Service sales")+SUMIFS(Raw_Data!$C$4:$C$46,Raw_Data!$A$4:$A$46,E$3,Raw_Data!$B$4:$B$46,"Modernization sales"))/SUMIFS(Raw_Data!$C$4:$C$46,Raw_Data!$A$4:$A$46,E$3,Raw_Data!$B$4:$B$46,"Sales"))) -> 0.65 | F13: =IF(ISNUMBER(B13),SUMPRODUCT(--ISNUMBER(B13:E13),--(B13:E13>B13))+1&" of "&COUNT(B13:E13),"n/d") -> 3 of 3 | G13: Schindler does not disclose its mix
A14: Employees | B14: =IF(COUNTIFS(Raw_Data!$A$4:$A$46,B$3,Raw_Data!$B$4:$B$46,"Employees")=0,"n/d",SUMIFS(Raw_Data!$C$4:$C$46,Raw_Data!$A$4:$A$46,B$3,Raw_Data!$B$4:$B$46,"Employees")) -> 64978 | C14: =IF(COUNTIFS(Raw_Data!$A$4:$A$46,C$3,Raw_Data!$B$4:$B$46,"Employees")=0,"n/d",SUMIFS(Raw_Data!$C$4:$C$46,Raw_Data!$A$4:$A$46,C$3,Raw_Data!$B$4:$B$46,"Employees")) -> 72000 | D14: =IF(COUNTIFS(Raw_Data!$A$4:$A$46,D$3,Raw_Data!$B$4:$B$46,"Employees")=0,"n/d",SUMIFS(Raw_Data!$C$4:$C$46,Raw_Data!$A$4:$A$46,D$3,Raw_Data!$B$4:$B$46,"Employees")) -> 67381 | E14: =IF(COUNTIFS(Raw_Data!$A$4:$A$46,E$3,Raw_Data!$B$4:$B$46,"Employees")=0,"n/d",SUMIFS(Raw_Data!$C$4:$C$46,Raw_Data!$A$4:$A$46,E$3,Raw_Data!$B$4:$B$46,"Employees")) -> 50000 | F14: =IF(ISNUMBER(B14),SUMPRODUCT(--ISNUMBER(B14:E14),--(B14:E14>B14))+1&" of "&COUNT(B14:E14),"n/d") -> 3 of 4 | G14: Headcount or FTE, as reported
A15: Sales per employee (EUR k) | B15: =IF(AND(ISNUMBER(B7),ISNUMBER(B14)),B7/B14*1000,"n/d") -> 173.06165 | C15: =IF(AND(ISNUMBER(C7),ISNUMBER(C14)),C7/C14*1000,"n/d") -> 177.37217 | D15: =IF(AND(ISNUMBER(D7),ISNUMBER(D14)),D7/D14*1000,"n/d") -> 173.38762 | E15: =IF(AND(ISNUMBER(E7),ISNUMBER(E14)),E7/E14*1000,"n/d") -> 184 | F15: =IF(ISNUMBER(B15),SUMPRODUCT(--ISNUMBER(B15:E15),--(B15:E15>B15))+1&" of "&COUNT(B15:E15),"n/d") -> 4 of 4 | G15: Productivity proxy
A16: Units under maintenance (m) | B16: =IF(COUNTIFS(Raw_Data!$A$4:$A$46,B$3,Raw_Data!$B$4:$B$46,"Units under maintenance")=0,"n/d",SUMIFS(Raw_Data!$C$4:$C$46,Raw_Data!$A$4:$A$46,B$3,Raw_Data!$B$4:$B$46,"Units under maintenance")) -> 1.8 | C16: =IF(COUNTIFS(Raw_Data!$A$4:$A$46,C$3,Raw_Data!$B$4:$B$46,"Units under maintenance")=0,"n/d",SUMIFS(Raw_Data!$C$4:$C$46,Raw_Data!$A$4:$A$46,C$3,Raw_Data!$B$4:$B$46,"Units under maintenance")) -> 2.5 | D16: =IF(COUNTIFS(Raw_Data!$A$4:$A$46,D$3,Raw_Data!$B$4:$B$46,"Units under maintenance")=0,"n/d",SUMIFS(Raw_Data!$C$4:$C$46,Raw_Data!$A$4:$A$46,D$3,Raw_Data!$B$4:$B$46,"Units under maintenance")) -> n/d | E16: =IF(COUNTIFS(Raw_Data!$A$4:$A$46,E$3,Raw_Data!$B$4:$B$46,"Units under maintenance")=0,"n/d",SUMIFS(Raw_Data!$C$4:$C$46,Raw_Data!$A$4:$A$46,E$3,Raw_Data!$B$4:$B$46,"Units under maintenance")) -> 1.4 | F16: =IF(ISNUMBER(B16),SUMPRODUCT(--ISNUMBER(B16:E16),--(B16:E16>B16))+1&" of "&COUNT(B16:E16),"n/d") -> 2 of 3 | G16: Approximate figures; Schindler not collected
A17: Service & mod. sales per maintained unit (EUR) | B17: =IF(AND(ISNUMBER(B13),ISNUMBER(B16)),B7*B13/B16,"n/d") -> 3970.8889 | C17: =IF(AND(ISNUMBER(C13),ISNUMBER(C16)),C7*C13/C16,"n/d") -> 3342.3009 | D17: =IF(AND(ISNUMBER(D13),ISNUMBER(D16)),D7*D13/D16,"n/d") -> n/d | E17: =IF(AND(ISNUMBER(E13),ISNUMBER(E16)),E7*E13/E16,"n/d") -> 4271.4286 | F17: =IF(ISNUMBER(B17),SUMPRODUCT(--ISNUMBER(B17:E17),--(B17:E17>B17))+1&" of "&COUNT(B17:E17),"n/d") -> 2 of 3 | G17: Indicative only: units and revenue definitions differ
A19: KONE gap to best peer, adjusted EBIT margin (pp) | B19: =(MAX(B10:E10)-B10)*100 -> 4.7
A20: KONE adjusted EBIT gap to Otis margin (EUR m at KONE sales) | B20: =(C10-B10)*B7 -> 528.5244
A21: KONE Greater China share of sales (%) | B21: =SUMIFS(Raw_Data!$C$4:$C$46,Raw_Data!$A$4:$A$46,B$3,Raw_Data!$B$4:$B$46,"Sales Greater China")/SUMIFS(Raw_Data!$C$4:$C$46,Raw_Data!$A$4:$A$46,B$3,Raw_Data!$B$4:$B$46,"Sales") -> 0.19261552

Sheet ProForma
A1: Pro forma KONE + TKE vs Otis and Schindler (EUR millions)
A2: Simple sum of last reported fiscal years. Ignores divestments, integration costs and financing.
A4: Metric | B4: KONE | C4: TKE | D4: KONE + TKE | E4: Otis | F4: Schindler | G4: Note
A5: Sales | B5: =Benchmark!B7 -> 11245.2 | C5: =Benchmark!E7 -> 9200 | D5: =B5+C5 -> 20445.2 | E5: =Benchmark!C7 -> 12770.796 | F5: =Benchmark!D7 -> 11683.031 | G5: TKE fiscal year ends 30 Sep 2025
A6: Adjusted EBIT, before synergies | B6: =Benchmark!B11 -> 1371.9144 | C6: =Benchmark!E11 -> 1361.6 | D6: =B6+C6 -> 2733.5144 | E6: =Benchmark!C11 -> 2158.2646 | F6: =Benchmark!D11 -> 1553.8431 | G6: Sales x company-defined adjusted margin
A7: Adjusted EBIT margin, before synergies | B7: =B6/B5 -> 0.122 | C7: =C6/C5 -> 0.148 | D7: =D6/D5 -> 0.13369957 | E7: =E6/E5 -> 0.169 | F7: =F6/F5 -> 0.133
A8: Synergies realised (selected scenario) | D8: =Inputs!B7*Inputs!B17 -> 350 | G8: Announced EUR 700m run-rate x scenario share (Inputs)
A9: Adjusted EBIT, after synergies | D9: =D6+D8 -> 3083.5144
A10: Adjusted EBIT margin, after synergies | D10: =D9/D5 -> 0.1508185 | G10: Compare with Otis in E7
A11: Scale vs Otis (sales multiple) | D11: =D5/E5 -> 1.6009338
A12: Employees | B12: =Benchmark!B14 -> 64978 | C12: =Benchmark!E14 -> 50000 | D12: =B12+C12 -> 114978 | E12: =Benchmark!C14 -> 72000 | F12: =Benchmark!D14 -> 67381
A13: Units under maintenance (m) | B13: =Benchmark!B16 -> 1.8 | C13: =Benchmark!E16 -> 1.4 | D13: =B13+C13 -> 3.2 | E13: =Benchmark!C16 -> 2.5 | G13: Announced combined figure: ~3.2m
A14: Service & modernization share | B14: =Benchmark!B13 -> 0.63561342 | C14: =Benchmark!E13 -> 0.65 | D14: =(B5*B14+C5*C14)/D5 -> 0.64208714 | E14: =Benchmark!C13 -> 0.65428591
A15: US share of sales | B15: =SUMIFS(Raw_Data!$C$4:$C$46,Raw_Data!$A$4:$A$46,"KONE",Raw_Data!$B$4:$B$46,"US share of sales") -> 0.21 | C15: =SUMIFS(Raw_Data!$C$4:$C$46,Raw_Data!$A$4:$A$46,"TKE",Raw_Data!$B$4:$B$46,"US share of sales") -> 0.45 | D15: =(B5*B15+C5*C15)/D5 -> 0.31799601 | G15: TKE US share from press report
A18: Sensitivity: combined adjusted EBIT margin by synergy realisation
A19: Synergies realised | B19: EUR m | C19: Combined margin | D19: Gap to Otis (pp)
A20: 0 | B20: =Inputs!$B$7*A20 -> 0 | C20: =($D$6+B20)/$D$5 -> 0.13369957 | D20: =(C20-$E$7)*100 -> -3.5300432
A21: 0.25 | B21: =Inputs!$B$7*A21 -> 175 | C21: =($D$6+B21)/$D$5 -> 0.14225903 | D21: =(C21-$E$7)*100 -> -2.6740966
A22: 0.5 | B22: =Inputs!$B$7*A22 -> 350 | C22: =($D$6+B22)/$D$5 -> 0.1508185 | D22: =(C22-$E$7)*100 -> -1.81815
A23: 0.75 | B23: =Inputs!$B$7*A23 -> 525 | C23: =($D$6+B23)/$D$5 -> 0.15937797 | D23: =(C23-$E$7)*100 -> -0.96220335
A24: 1 | B24: =Inputs!$B$7*A24 -> 700 | C24: =($D$6+B24)/$D$5 -> 0.16793743 | D24: =(C24-$E$7)*100 -> -0.10625673

Sheet Checks
A1: Checks
A3: # | B3: Test | C3: Calculated | D3: Expected | E3: Tolerance | F3: Result
A4: 1 | B4: KONE business lines sum to group sales | C4: =SUMIFS(Raw_Data!$C$4:$C$46,Raw_Data!$A$4:$A$46,"KONE",Raw_Data!$B$4:$B$46,"New equipment sales")+SUMIFS(Raw_Data!$C$4:$C$46,Raw_Data!$A$4:$A$46,"KONE",Raw_Data!$B$4:$B$46,"Service sales")+SUMIFS(Raw_Data!$C$4:$C$46,Raw_Data!$A$4:$A$46,"KONE",Raw_Data!$B$4:$B$46,"Modernization sales") -> 11245.3 | D4: =SUMIFS(Raw_Data!$C$4:$C$46,Raw_Data!$A$4:$A$46,"KONE",Raw_Data!$B$4:$B$46,"Sales") -> 11245.2 | E4: 0.5 | F4: =IF(ABS(C4-D4)<=E4,"OK","CHECK") -> OK
A5: 2 | B5: KONE areas sum to group sales | C5: =SUMIFS(Raw_Data!$C$4:$C$46,Raw_Data!$A$4:$A$46,"KONE",Raw_Data!$B$4:$B$46,"Sales Americas")+SUMIFS(Raw_Data!$C$4:$C$46,Raw_Data!$A$4:$A$46,"KONE",Raw_Data!$B$4:$B$46,"Sales Europe")+SUMIFS(Raw_Data!$C$4:$C$46,Raw_Data!$A$4:$A$46,"KONE",Raw_Data!$B$4:$B$46,"Sales APMEA")+SUMIFS(Raw_Data!$C$4:$C$46,Raw_Data!$A$4:$A$46,"KONE",Raw_Data!$B$4:$B$46,"Sales Greater China") -> 11245.2 | D5: =SUMIFS(Raw_Data!$C$4:$C$46,Raw_Data!$A$4:$A$46,"KONE",Raw_Data!$B$4:$B$46,"Sales") -> 11245.2 | E5: 0.5 | F5: =IF(ABS(C5-D5)<=E5,"OK","CHECK") -> OK
A6: 3 | B6: Otis segments sum to group sales | C6: =SUMIFS(Raw_Data!$C$4:$C$46,Raw_Data!$A$4:$A$46,"Otis",Raw_Data!$B$4:$B$46,"New equipment sales")+SUMIFS(Raw_Data!$C$4:$C$46,Raw_Data!$A$4:$A$46,"Otis",Raw_Data!$B$4:$B$46,"Service sales") -> 14431 | D6: =SUMIFS(Raw_Data!$C$4:$C$46,Raw_Data!$A$4:$A$46,"Otis",Raw_Data!$B$4:$B$46,"Sales") -> 14431 | E6: 0.5 | F6: =IF(ABS(C6-D6)<=E6,"OK","CHECK") -> OK
A7: 4 | B7: Schindler regions sum to group revenue | C7: =SUMIFS(Raw_Data!$C$4:$C$46,Raw_Data!$A$4:$A$46,"Schindler",Raw_Data!$B$4:$B$46,"Sales EMEA")+SUMIFS(Raw_Data!$C$4:$C$46,Raw_Data!$A$4:$A$46,"Schindler",Raw_Data!$B$4:$B$46,"Sales Americas")+SUMIFS(Raw_Data!$C$4:$C$46,Raw_Data!$A$4:$A$46,"Schindler",Raw_Data!$B$4:$B$46,"Sales Asia-Pacific") -> 10947 | D7: =SUMIFS(Raw_Data!$C$4:$C$46,Raw_Data!$A$4:$A$46,"Schindler",Raw_Data!$B$4:$B$46,"Sales") -> 10947 | E7: 0.5 | F7: =IF(ABS(C7-D7)<=E7,"OK","CHECK") -> OK
A8: 5 | B8: KONE adjusted EBIT / sales matches reported margin | C8: =SUMIFS(Raw_Data!$C$4:$C$46,Raw_Data!$A$4:$A$46,"KONE",Raw_Data!$B$4:$B$46,"Adjusted EBIT")/SUMIFS(Raw_Data!$C$4:$C$46,Raw_Data!$A$4:$A$46,"KONE",Raw_Data!$B$4:$B$46,"Sales") -> 0.12176751 | D8: =SUMIFS(Raw_Data!$C$4:$C$46,Raw_Data!$A$4:$A$46,"KONE",Raw_Data!$B$4:$B$46,"Adjusted EBIT margin") -> 0.122 | E8: 0.001 | F8: =IF(ABS(C8-D8)<=E8,"OK","CHECK") -> OK
A9: 6 | B9: Otis adjusted EBIT / sales matches reported margin | C9: =SUMIFS(Raw_Data!$C$4:$C$46,Raw_Data!$A$4:$A$46,"Otis",Raw_Data!$B$4:$B$46,"Adjusted EBIT")/SUMIFS(Raw_Data!$C$4:$C$46,Raw_Data!$A$4:$A$46,"Otis",Raw_Data!$B$4:$B$46,"Sales") -> 0.16866468 | D9: =SUMIFS(Raw_Data!$C$4:$C$46,Raw_Data!$A$4:$A$46,"Otis",Raw_Data!$B$4:$B$46,"Adjusted EBIT margin") -> 0.169 | E9: 0.001 | F9: =IF(ABS(C9-D9)<=E9,"OK","CHECK") -> OK
A10: 7 | B10: Pro forma sales close to announced EUR 20.5bn | C10: =ProForma!D5 -> 20445.2 | D10: =SUMIFS(Raw_Data!$C$4:$C$46,Raw_Data!$A$4:$A$46,"KONE + TKE",Raw_Data!$B$4:$B$46,"Combined sales (announced)") -> 20500 | E10: 200 | F10: =IF(ABS(C10-D10)<=E10,"OK","CHECK") -> OK
A11: 8 | B11: Pro forma units close to announced 3.2m | C11: =ProForma!D13 -> 3.2 | D11: =SUMIFS(Raw_Data!$C$4:$C$46,Raw_Data!$A$4:$A$46,"KONE + TKE",Raw_Data!$B$4:$B$46,"Combined units under maintenance (announced)") -> 3.2 | E11: 0.1 | F11: =IF(ABS(C11-D11)<=E11,"OK","CHECK") -> OK
A12: 9 | B12: FX rates are positive | C12: =MIN(Inputs!B4:B6) -> 0.937 | D12: =0 -> 0 | E12: 1 | F12: =IF(C12>D12,"OK","CHECK") -> OK
A13: 10 | B13: Every Raw_Data row has a source | C13: =COUNTA(Raw_Data!G4:G46) -> 43 | D13: =COUNTA(Raw_Data!A4:A46) -> 43 | E13: 0 | F13: =IF(ABS(C13-D13)<=E13,"OK","CHECK") -> OK
B15: Overall result | F15: =IF(COUNTIF(F4:F13,"OK")=10,"ALL OK","CHECK") -> ALL OK

Sheet Dashboard
A1: Dashboard
A3: Chart data (linked)
A4: Company | B4: Sales (EUR bn) | C4: Adj. EBIT margin | D4: Service & mod. share
A5: KONE | B5: =Benchmark!B7/1000 -> 11.2452 | C5: =Benchmark!B10 -> 0.122 | D5: =IF(ISNUMBER(Benchmark!B13),Benchmark!B13,0) -> 0.63561342
A6: Otis | B6: =Benchmark!C7/1000 -> 12.770796 | C6: =Benchmark!C10 -> 0.169 | D6: =IF(ISNUMBER(Benchmark!C13),Benchmark!C13,0) -> 0.65428591
A7: Schindler | B7: =Benchmark!D7/1000 -> 11.683031 | C7: =Benchmark!D10 -> 0.133 | D7: =IF(ISNUMBER(Benchmark!D13),Benchmark!D13,0) -> 0
A8: TKE | B8: =Benchmark!E7/1000 -> 9.2 | C8: =Benchmark!E10 -> 0.148 | D8: =IF(ISNUMBER(Benchmark!E13),Benchmark!E13,0) -> 0.65
A9: KONE + TKE | B9: =ProForma!D5/1000 -> 20.4452 | C9: =ProForma!D10 -> 0.1508185 | D9: =ProForma!D14 -> 0.64208714
A10: Schindler mix not disclosed (shown as 0). KONE + TKE margin includes selected synergy scenario.
